<?xml version="1.0" encoding="utf-8"?><testsuites><testsuite errors="0" failures="4" hostname="zhaoyingdeair" name="pytest" skipped="0" tests="6" time="0.111" timestamp="2021-04-13T21:17:49.697066"><testcase classname="test_pytest001" name="test_answer" time="0.002"><failure message="assert 4 == 5&#10; +  where 4 = inc(3)">def test_answer():
&gt;       assert inc(3) == 5
E       assert 4 == 5
E        +  where 4 = inc(3)

test_pytest001.py:8: AssertionError</failure></testcase><testcase classname="test_pytest.test_002" name="test_mytest" time="0.001" /><testcase classname="test_pytest.test_class.TestClass" name="test_one" time="0.001" /><testcase classname="test_pytest.test_class.TestClass" name="test_two" time="0.001"><failure message="AssertionError: assert False&#10; +  where False = hasattr('hello', 'check')">self = &lt;test_pytest.test_class.TestClass object at 0x10431a490&gt;

    def test_two(self):
        x = "hello"
&gt;       assert hasattr(x, "check")
E       AssertionError: assert False
E        +  where False = hasattr('hello', 'check')

test_pytest/test_class.py:13: AssertionError</failure></testcase><testcase classname="test_pytest.test_instance.TestClassDemoInstance" name="test_one" time="0.002"><failure message="assert 0">self = &lt;test_pytest.test_instance.TestClassDemoInstance object at 0x10431ac90&gt;

    def test_one(self):
&gt;       assert 0
E       assert 0

test_pytest/test_instance.py:3: AssertionError</failure></testcase><testcase classname="test_pytest.test_instance.TestClassDemoInstance" name="test_two" time="0.002"><failure message="assert 0">self = &lt;test_pytest.test_instance.TestClassDemoInstance object at 0x10431ca50&gt;

    def test_two(self):
&gt;       assert 0
E       assert 0

test_pytest/test_instance.py:6: AssertionError</failure></testcase></testsuite></testsuites>